<?xml version="1.0" ?>
<!-- =================================================================================== -->
<!-- |    This document was autogenerated by xacro from kuka_lwr_assembled.urdf.xacro  | -->
<!-- |    EDITING THIS FILE BY HAND IS NOT RECOMMENDED                                 | -->
<!-- =================================================================================== -->
<robot name="kuka_lwr_assembled" xmlns:controller="http://playerstage.sourceforge.net/gazebo/xmlschema/#controller" xmlns:interface="http://playerstage.sourceforge.net/gazebo/xmlschema/#interface" xmlns:sensor="http://playerstage.sourceforge.net/gazebo/xmlschema/#sensor" xmlns:xacro="http://ros.org/wiki/xacro">
  <material name="DarkGrey">
    <color rgba="0.3 0.3 0.3 1.0"/>
  </material>
  <material name="LightGrey">
    <color rgba="0.8 0.8 0.8 1.0"/>
  </material>
  <material name="Red">
    <color rgba="0.3 0.3 0.3 1.0"/>
  </material>
  <material name="Black">
    <color rgba="0 0 0 1.0"/>
  </material>
  <material name="Orange">
    <color rgba="1.0 0.487 0 1.0"/>
  </material>
  <material name="Silver">
    <color rgba="1.0 1.0 1.0 1.0"/>
  </material>
  <material name="Grey">
    <color rgba="0.7 0.7 0.7 1.0"/>
  </material>
  <material name="Blue">
    <color rgba="0.0 0.0 0.8 1.0"/>
  </material>
  <material name="HandGray">
    <color rgba="0.953 0.996 0.694 1.0"/>
  </material>
  <material name="SickBlue">
    <color rgba="0.3058 0.5921 0.7294 1.0"/>
  </material>
  <material name="Schunk/LightGrey">
    <color rgba="0.7 0.7 0.7 1"/>
  </material>
  <link name="world_link"/>
  <joint name="world_table_base_joint" type="fixed">
    <origin xyz="0.75 -0.0748 0"/>
    <parent link="world_link"/>
    <child link="table_link"/>
  </joint>
  <link name="table_link">
    <!-- 		<visual>
			<origin xyz="0.29 0.355 0.34"/>
			<geometry>
				<box size="0.04 0.04 0.68"/>
			</geometry>
			<material name="LightGrey"/>
		</visual>
		<visual>
			<origin xyz="-0.29 0.355 0.34"/>
			<geometry>
				<box size="0.04 0.04 0.68"/>
			</geometry>
			<material name="DarkGrey"/>
		</visual>
		<visual>
			<origin xyz="0.29 -0.355 0.34"/>
			<geometry>
				<box size="0.04 0.04 0.68"/>
			</geometry>
			<material name="DarkGrey"/>
		</visual>
		<visual>
			<origin xyz="-0.29 -0.355 0.34"/>
			<geometry>
				<box size="0.04 0.04 0.68"/>
			</geometry>
			<material name="DarkGrey"/>
		</visual> -->
    <visual>
      <origin xyz="0 0 0.695"/>
      <geometry>
        <box size="0.7 1.4 0.03"/>
      </geometry>
      <material name="LightGrey"/>
    </visual>
    <!-- Moveit doesn't work using multiple collision geometries for a link -->
    <!-- 		<collision>
			<origin xyz="0.29 0.355 0.34"/>
			<geometry>
				<box size="0.04 0.04 0.68"/>
			</geometry>
		</collision>
		<collision>
			<origin xyz="-0.29 0.355 0.34"/>
			<geometry>
				<box size="0.04 0.04 0.68"/>
			</geometry>
		</collision>
		<collision>
			<origin xyz="0.29 -0.355 0.34"/>
			<geometry>
				<box size="0.04 0.04 0.68"/>
			</geometry>
		</collision>
		<collision>
			<origin xyz="-0.29 -0.355 0.34"/>
			<geometry>
				<box size="0.04 0.04 0.68"/>
			</geometry>
		</collision> -->
    <collision>
      <origin xyz="0 0 0.695"/>
      <geometry>
        <box size="0.7 1.4 0.03"/>
      </geometry>
    </collision>
  </link>
  <joint name="world_torso_base_joint" type="fixed">
    <origin xyz="0 0 0"/>
    <parent link="world_link"/>
    <child link="torso_link"/>
  </joint>
  <link name="torso_link">
    <visual>
      <geometry>
        <mesh filename="package://uibk_robot/meshes/torso.stl"/>
      </geometry>
      <material name="Silver"/>
    </visual>
  </link>
  <joint name="torso_leftArm_arm_base_joint" type="fixed">
    <origin rpy="-1.9392 -0.3456 -0.2952" xyz="-0.0199 0.0661 1.34"/>
    <parent link="torso_link"/>
    <child link="calib_leftArm_arm_base_link"/>
  </joint>
  <link name="calib_leftArm_arm_base_link">
    <inertial>
      <mass value="2.0"/>
      <origin xyz="0 0 0.055"/>
      <inertia ixx="0.00381666666667" ixy="0" ixz="0" iyy="0.0036" iyz="0" izz="0.00381666666667"/>
    </inertial>
    <visual>
      <origin rpy="0 0 0" xyz="0 0 0"/>
      <geometry>
        <mesh filename="package://uibk_robot/meshes/lwr/base.STL"/>
      </geometry>
      <material name="Orange"/>
    </visual>
    <collision>
      <origin rpy="0 0 3.14159265359" xyz="0 0 0.055"/>
      <geometry>
        <!--          <mesh filename="package://uibk_robot/meshes/lwr/convex/arm_base_convex.stl"/> -->
        <cylinder length="0.11" radius="0.07"/>
      </geometry>
    </collision>
  </link>
  <joint name="leftArm_arm_0_joint" type="revolute">
    <origin rpy="0 0 0" xyz="0 0 0.11"/>
    <axis xyz="0 0 1"/>
    <limit effort="204" lower="-2.96705972839" upper="2.96705972839" velocity="1.91986217719"/>
    <safety_controller k_position="30" k_velocity="30" soft_lower_limit="-2.93215314335" soft_upper_limit="2.93215314335"/>
    <dynamics damping="1.0"/>
    <parent link="calib_leftArm_arm_base_link"/>
    <child link="leftArm_arm_1_link"/>
  </joint>
  <link name="leftArm_arm_1_link">
    <inertial>
      <mass value="2.0"/>
      <origin rpy="0 0 0" xyz="0 -0.06 0.130"/>
      <inertia ixx="0.0136666666667" ixy="0" ixz="0" iyy="0.003" iyz="0" izz="0.0118666666667"/>
    </inertial>
    <visual>
      <origin rpy="0 0 0" xyz="0 0 -0.008"/>
      <geometry>
        <mesh filename="package://uibk_robot/meshes/lwr/link_1.STL"/>
      </geometry>
      <material name="Orange"/>
    </visual>
    <!--
      <collision>
        <origin xyz="0 0 0" rpy="0 0 0"/>
        <geometry>
          <mesh filename="package://uibk_robot/meshes/lwr/convex/arm_segment_a_convex.stl"/>
        </geometry>
      </collision>
 -->
    <collision>
      <origin rpy="0 0 0" xyz="0 0 0.0"/>
      <geometry>
        <sphere radius="0.07"/>
      </geometry>
    </collision>
    <collision>
      <origin rpy="0 0 0" xyz="0 -0.06 0.2"/>
      <geometry>
        <sphere radius="0.07"/>
      </geometry>
    </collision>
    <collision>
      <origin rpy="0.291 0 0" xyz="0 -0.03 0.1"/>
      <geometry>
        <cylinder length="0.208" radius="0.07"/>
      </geometry>
    </collision>
  </link>
  <gazebo reference="leftArm_arm_1_link">
    <gravity>false</gravity>
  </gazebo>
  <transmission name="leftArm_arm_0_trans" type="SimpleTransmission">
    <actuator name="leftArm_arm_0_motor"/>
    <joint name="leftArm_arm_0_joint"/>
    <mechanicalReduction>1.0</mechanicalReduction>
  </transmission>
  <joint name="leftArm_arm_1_joint" type="revolute">
    <origin rpy="0 0 0" xyz="0 0 0.2005"/>
    <axis xyz="0 1 0"/>
    <limit effort="306" lower="-2.09439510239" upper="2.09439510239" velocity="1.91986217719"/>
    <safety_controller k_position="30" k_velocity="30" soft_lower_limit="-2.05948851735" soft_upper_limit="2.05948851735"/>
    <dynamics damping="1.0" friction="10"/>
    <parent link="leftArm_arm_1_link"/>
    <child link="leftArm_arm_2_link"/>
  </joint>
  <link name="leftArm_arm_2_link">
    <inertial>
      <mass value="2.0"/>
      <origin rpy="0 0 0" xyz="0 0.06 0.07"/>
      <inertia ixx="0.0136666666667" ixy="0" ixz="0" iyy="0.003" iyz="0" izz="0.0118666666667"/>
    </inertial>
    <visual>
      <origin rpy="0 0 0" xyz="0 0 0.0"/>
      <geometry>
        <mesh filename="package://uibk_robot/meshes/lwr/link_2.STL"/>
      </geometry>
      <material name="Orange"/>
    </visual>
    <!--
      <collision>
        <origin xyz="0 0 0.2" rpy="${M_PI} 0 0"/>
        <geometry>
          <mesh filename="package://uibk_robot/meshes/lwr/convex/arm_segment_b_convex.stl"/>
        </geometry>
      </collision>
-->
    <collision>
      <origin rpy="0 0 0" xyz="0 0 0.2"/>
      <geometry>
        <sphere radius="0.07"/>
      </geometry>
    </collision>
    <collision>
      <origin rpy="0 0 0" xyz="0 0.06 0.0"/>
      <geometry>
        <sphere radius="0.07"/>
      </geometry>
    </collision>
    <collision>
      <origin rpy="0.291 0 0" xyz="0 0.03 0.1"/>
      <geometry>
        <cylinder length="0.208" radius="0.07"/>
      </geometry>
    </collision>
  </link>
  <gazebo reference="leftArm_arm_2_link">
    <gravity>false</gravity>
  </gazebo>
  <transmission name="leftArm_arm_1_trans" type="SimpleTransmission">
    <actuator name="leftArm_arm_1_motor"/>
    <joint name="leftArm_arm_1_joint"/>
    <mechanicalReduction>1.0</mechanicalReduction>
  </transmission>
  <joint name="leftArm_arm_2_joint" type="revolute">
    <origin rpy="0 0 0" xyz="0 0 0.20"/>
    <axis xyz="0 0 1"/>
    <limit effort="204" lower="-2.96705972839" upper="2.96705972839" velocity="2.26892802759"/>
    <safety_controller k_position="30" k_velocity="30" soft_lower_limit="-2.93215314335" soft_upper_limit="2.93215314335"/>
    <dynamics damping="1.0"/>
    <parent link="leftArm_arm_2_link"/>
    <child link="leftArm_arm_3_link"/>
  </joint>
  <link name="leftArm_arm_3_link">
    <inertial>
      <mass value="2.0"/>
      <origin rpy="0 0 0" xyz="0 0.06 0.130"/>
      <inertia ixx="0.0136666666667" ixy="0" ixz="0" iyy="0.003" iyz="0" izz="0.0118666666667"/>
    </inertial>
    <visual>
      <origin rpy="0 0 0" xyz="0 0 -0.008"/>
      <geometry>
        <mesh filename="package://uibk_robot/meshes/lwr/link_3.STL"/>
      </geometry>
      <material name="Orange"/>
    </visual>
    <!--
      <collision>
        <origin xyz="0 0 0" rpy="0 0 ${M_PI}"/>
        <geometry>
          <mesh filename="package://uibk_robot/meshes/lwr/convex/arm_segment_a_convex.stl"/>
        </geometry>
      </collision>
-->
    <collision>
      <origin rpy="0 0 0" xyz="0 0 0.0"/>
      <geometry>
        <sphere radius="0.07"/>
      </geometry>
    </collision>
    <collision>
      <origin rpy="0 0 0" xyz="0 0.06 0.2"/>
      <geometry>
        <sphere radius="0.07"/>
      </geometry>
    </collision>
    <collision>
      <origin rpy="-0.291 0 0" xyz="0 0.03 0.1"/>
      <geometry>
        <cylinder length="0.208" radius="0.07"/>
      </geometry>
    </collision>
  </link>
  <gazebo reference="leftArm_arm_3_link">
    <gravity>false</gravity>
  </gazebo>
  <transmission name="leftArm_arm_2_trans" type="SimpleTransmission">
    <actuator name="leftArm_arm_2_motor"/>
    <joint name="leftArm_arm_2_joint"/>
    <mechanicalReduction>1.0</mechanicalReduction>
  </transmission>
  <joint name="leftArm_arm_3_joint" type="revolute">
    <origin rpy="0 0 0" xyz="0 0 0.20"/>
    <axis xyz="0 -1 0"/>
    <limit effort="306" lower="-2.09439510239" upper="2.09439510239" velocity="2.26892802759"/>
    <safety_controller k_position="30" k_velocity="30" soft_lower_limit="-2.05948851735" soft_upper_limit="2.05948851735"/>
    <dynamics damping="1.0"/>
    <parent link="leftArm_arm_3_link"/>
    <child link="leftArm_arm_4_link"/>
  </joint>
  <link name="leftArm_arm_4_link">
    <inertial>
      <mass value="2.0"/>
      <origin rpy="0 0 0" xyz="0 -0.06 0.07"/>
      <inertia ixx="0.0136666666667" ixy="0" ixz="0" iyy="0.003" iyz="0" izz="0.0118666666667"/>
    </inertial>
    <visual>
      <origin rpy="0 0 0" xyz="0 0 0.0"/>
      <geometry>
        <mesh filename="package://uibk_robot/meshes/lwr/link_4.STL"/>
      </geometry>
      <material name="Orange"/>
    </visual>
    <!--
      <collision>
        <origin xyz="0 0 0.2" rpy="0 ${M_PI} 0"/>
        <geometry>
          <mesh filename="package://uibk_robot/meshes/lwr/convex/arm_segment_b_convex.stl"/>
        </geometry>
      </collision>
-->
    <collision>
      <origin rpy="0 0 0" xyz="0 0 0.2"/>
      <geometry>
        <sphere radius="0.07"/>
      </geometry>
    </collision>
    <collision>
      <origin rpy="0 0 0" xyz="0 -0.06 0.0"/>
      <geometry>
        <sphere radius="0.07"/>
      </geometry>
    </collision>
    <collision>
      <origin rpy="-0.291 0 0" xyz="0 -0.03 0.1"/>
      <geometry>
        <cylinder length="0.208" radius="0.07"/>
      </geometry>
    </collision>
  </link>
  <gazebo reference="leftArm_arm_4_link">
    <gravity>false</gravity>
  </gazebo>
  <transmission name="leftArm_arm_3_trans" type="SimpleTransmission">
    <actuator name="leftArm_arm_3_motor"/>
    <joint name="leftArm_arm_3_joint"/>
    <mechanicalReduction>1.0</mechanicalReduction>
  </transmission>
  <joint name="leftArm_arm_4_joint" type="revolute">
    <origin rpy="0 0 0" xyz="0 0 0.20"/>
    <axis xyz="0 0 1"/>
    <limit effort="204" lower="-2.96705972839" upper="2.96705972839" velocity="2.26892802759"/>
    <safety_controller k_position="30" k_velocity="30" soft_lower_limit="-2.93215314335" soft_upper_limit="2.93215314335"/>
    <dynamics damping="1.0"/>
    <parent link="leftArm_arm_4_link"/>
    <child link="leftArm_arm_5_link"/>
  </joint>
  <link name="leftArm_arm_5_link">
    <inertial>
      <mass value="2.0"/>
      <origin rpy="0 0 0" xyz="0 0 0.124"/>
      <inertia ixx="0.0126506666667" ixy="0" ixz="0" iyy="0.003" iyz="0" izz="0.0108506666667"/>
    </inertial>
    <visual>
      <origin rpy="0 0 0" xyz="0 0 -0.008"/>
      <geometry name="leftArm_arm_5_geom">
        <mesh filename="package://uibk_robot/meshes/lwr/link_5.STL"/>
      </geometry>
      <material name="Orange"/>
    </visual>
    <!--
      <collision>
        <origin xyz="0 0 0" rpy="0 0 0"/>
        <geometry>
          <mesh filename="package://uibk_robot/meshes/lwr/convex/arm_segment_last_convex.stl"/>
        </geometry>
      </collision>
-->
    <collision>
      <origin rpy="0 0 0" xyz="0 0 0.0"/>
      <geometry>
        <sphere radius="0.07"/>
      </geometry>
    </collision>
    <collision>
      <origin rpy="0 0 0" xyz="0 -0.04 0.19"/>
      <geometry>
        <sphere radius="0.07"/>
      </geometry>
    </collision>
    <collision>
      <origin rpy="0.207 0 0" xyz="0 -0.02 0.095"/>
      <geometry>
        <cylinder length="0.198" radius="0.07"/>
      </geometry>
    </collision>
  </link>
  <gazebo reference="leftArm_arm_5_link">
    <gravity>false</gravity>
  </gazebo>
  <transmission name="leftArm_arm_4_trans" type="SimpleTransmission">
    <actuator name="leftArm_arm_4_motor"/>
    <joint name="leftArm_arm_4_joint"/>
    <mechanicalReduction>1.0</mechanicalReduction>
  </transmission>
  <joint name="leftArm_arm_5_joint" type="revolute">
    <origin rpy="0 0 0" xyz="0 0 0.19"/>
    <axis xyz="0 1 0"/>
    <limit effort="306" lower="-2.09439510239" upper="2.09439510239" velocity="3.14159265359"/>
    <safety_controller k_position="30" k_velocity="30" soft_lower_limit="-2.05948851735" soft_upper_limit="2.05948851735"/>
    <dynamics damping="1.0"/>
    <parent link="leftArm_arm_5_link"/>
    <child link="leftArm_arm_6_link"/>
  </joint>
  <link name="leftArm_arm_6_link">
    <inertial>
      <mass value="0.2"/>
      <origin rpy="0 0 0" xyz="0 0 0.0625"/>
      <inertia ixx="0.000520833333333" ixy="0" ixz="0" iyy="0.000520833333333" iyz="0" izz="0.000520833333333"/>
    </inertial>
    <visual>
      <origin rpy="0 0 0" xyz="0 0 0"/>
      <geometry>
        <mesh filename="package://uibk_robot/meshes/lwr/link_6.STL"/>
      </geometry>
      <material name="Grey"/>
    </visual>
    <collision>
      <origin rpy="0 0 0" xyz="0 0 0"/>
      <geometry>
        <mesh filename="package://uibk_robot/meshes/lwr/convex/arm_wrist_convex.stl"/>
      </geometry>
    </collision>
  </link>
  <gazebo reference="leftArm_arm_6_link">
    <gravity>false</gravity>
  </gazebo>
  <transmission name="leftArm_arm_5_trans" type="SimpleTransmission">
    <actuator name="leftArm_arm_5_motor"/>
    <joint name="leftArm_arm_5_joint"/>
    <mechanicalReduction>1.0</mechanicalReduction>
  </transmission>
  <joint name="leftArm_arm_6_joint" type="revolute">
    <origin rpy="0 0 3.14159265359" xyz="0 0 0.078"/>
    <axis xyz="0 0 1"/>
    <limit effort="204" lower="-2.96705972839" upper="2.96705972839" velocity="3.14159265359"/>
    <safety_controller k_position="30" k_velocity="30" soft_lower_limit="-2.93215314335" soft_upper_limit="2.93215314335"/>
    <dynamics damping="1.0"/>
    <parent link="leftArm_arm_6_link"/>
    <child link="leftArm_arm_7_link"/>
  </joint>
  <link name="leftArm_arm_7_link">
    <inertial>
      <mass value="0.2"/>
      <origin xyz="0 0 0"/>
      <inertia ixx="0.0333333333333" ixy="0" ixz="0" iyy="0.0333333333333" iyz="0" izz="0.0333333333333"/>
    </inertial>
    <visual>
      <origin rpy="0 0 0" xyz="0 0 0"/>
      <geometry>
        <mesh filename="package://uibk_robot/meshes/lwr/link_7.STL"/>
      </geometry>
      <material name="DarkGrey"/>
    </visual>
    <collision>
      <origin rpy="0 0 -0.785398163397" xyz="0 0 0"/>
      <geometry>
        <cylinder length="0.05" radius="0.04"/>
      </geometry>
    </collision>
  </link>
  <gazebo reference="leftArm_arm_7_link">
    <gravity>false</gravity>
  </gazebo>
  <transmission name="leftArm_arm_6_trans" type="SimpleTransmission">
    <actuator name="leftArm_arm_6_motor"/>
    <joint name="leftArm_arm_6_joint"/>
    <mechanicalReduction>1.0</mechanicalReduction>
  </transmission>
  <joint name="torso_rightArm_arm_base_joint" type="fixed">
    <origin rpy="1.9386 0.3471 0.6879" xyz="-0.0202 -0.0663 1.3401"/>
    <parent link="torso_link"/>
    <child link="calib_rightArm_arm_base_link"/>
  </joint>
  <link name="calib_rightArm_arm_base_link">
    <inertial>
      <mass value="2.0"/>
      <origin xyz="0 0 0.055"/>
      <inertia ixx="0.00381666666667" ixy="0" ixz="0" iyy="0.0036" iyz="0" izz="0.00381666666667"/>
    </inertial>
    <visual>
      <origin rpy="0 0 0" xyz="0 0 0"/>
      <geometry>
        <mesh filename="package://uibk_robot/meshes/lwr/base.STL"/>
      </geometry>
      <material name="Orange"/>
    </visual>
    <collision>
      <origin rpy="0 0 3.14159265359" xyz="0 0 0.055"/>
      <geometry>
        <!--          <mesh filename="package://uibk_robot/meshes/lwr/convex/arm_base_convex.stl"/> -->
        <cylinder length="0.11" radius="0.07"/>
      </geometry>
    </collision>
  </link>
  <joint name="rightArm_arm_0_joint" type="revolute">
    <origin rpy="0 0 0" xyz="0 0 0.11"/>
    <axis xyz="0 0 1"/>
    <limit effort="204" lower="-2.96705972839" upper="2.96705972839" velocity="1.91986217719"/>
    <safety_controller k_position="30" k_velocity="30" soft_lower_limit="-2.93215314335" soft_upper_limit="2.93215314335"/>
    <dynamics damping="1.0"/>
    <parent link="calib_rightArm_arm_base_link"/>
    <child link="rightArm_arm_1_link"/>
  </joint>
  <link name="rightArm_arm_1_link">
    <inertial>
      <mass value="2.0"/>
      <origin rpy="0 0 0" xyz="0 -0.06 0.130"/>
      <inertia ixx="0.0136666666667" ixy="0" ixz="0" iyy="0.003" iyz="0" izz="0.0118666666667"/>
    </inertial>
    <visual>
      <origin rpy="0 0 0" xyz="0 0 -0.008"/>
      <geometry>
        <mesh filename="package://uibk_robot/meshes/lwr/link_1.STL"/>
      </geometry>
      <material name="Orange"/>
    </visual>
    <!--
      <collision>
        <origin xyz="0 0 0" rpy="0 0 0"/>
        <geometry>
          <mesh filename="package://uibk_robot/meshes/lwr/convex/arm_segment_a_convex.stl"/>
        </geometry>
      </collision>
 -->
    <collision>
      <origin rpy="0 0 0" xyz="0 0 0.0"/>
      <geometry>
        <sphere radius="0.07"/>
      </geometry>
    </collision>
    <collision>
      <origin rpy="0 0 0" xyz="0 -0.06 0.2"/>
      <geometry>
        <sphere radius="0.07"/>
      </geometry>
    </collision>
    <collision>
      <origin rpy="0.291 0 0" xyz="0 -0.03 0.1"/>
      <geometry>
        <cylinder length="0.208" radius="0.07"/>
      </geometry>
    </collision>
  </link>
  <gazebo reference="rightArm_arm_1_link">
    <gravity>false</gravity>
  </gazebo>
  <transmission name="rightArm_arm_0_trans" type="SimpleTransmission">
    <actuator name="rightArm_arm_0_motor"/>
    <joint name="rightArm_arm_0_joint"/>
    <mechanicalReduction>1.0</mechanicalReduction>
  </transmission>
  <joint name="rightArm_arm_1_joint" type="revolute">
    <origin rpy="0 0 0" xyz="0 0 0.2005"/>
    <axis xyz="0 1 0"/>
    <limit effort="306" lower="-2.09439510239" upper="2.09439510239" velocity="1.91986217719"/>
    <safety_controller k_position="30" k_velocity="30" soft_lower_limit="-2.05948851735" soft_upper_limit="2.05948851735"/>
    <dynamics damping="1.0" friction="10"/>
    <parent link="rightArm_arm_1_link"/>
    <child link="rightArm_arm_2_link"/>
  </joint>
  <link name="rightArm_arm_2_link">
    <inertial>
      <mass value="2.0"/>
      <origin rpy="0 0 0" xyz="0 0.06 0.07"/>
      <inertia ixx="0.0136666666667" ixy="0" ixz="0" iyy="0.003" iyz="0" izz="0.0118666666667"/>
    </inertial>
    <visual>
      <origin rpy="0 0 0" xyz="0 0 0.0"/>
      <geometry>
        <mesh filename="package://uibk_robot/meshes/lwr/link_2.STL"/>
      </geometry>
      <material name="Orange"/>
    </visual>
    <!--
      <collision>
        <origin xyz="0 0 0.2" rpy="${M_PI} 0 0"/>
        <geometry>
          <mesh filename="package://uibk_robot/meshes/lwr/convex/arm_segment_b_convex.stl"/>
        </geometry>
      </collision>
-->
    <collision>
      <origin rpy="0 0 0" xyz="0 0 0.2"/>
      <geometry>
        <sphere radius="0.07"/>
      </geometry>
    </collision>
    <collision>
      <origin rpy="0 0 0" xyz="0 0.06 0.0"/>
      <geometry>
        <sphere radius="0.07"/>
      </geometry>
    </collision>
    <collision>
      <origin rpy="0.291 0 0" xyz="0 0.03 0.1"/>
      <geometry>
        <cylinder length="0.208" radius="0.07"/>
      </geometry>
    </collision>
  </link>
  <gazebo reference="rightArm_arm_2_link">
    <gravity>false</gravity>
  </gazebo>
  <transmission name="rightArm_arm_1_trans" type="SimpleTransmission">
    <actuator name="rightArm_arm_1_motor"/>
    <joint name="rightArm_arm_1_joint"/>
    <mechanicalReduction>1.0</mechanicalReduction>
  </transmission>
  <joint name="rightArm_arm_2_joint" type="revolute">
    <origin rpy="0 0 0" xyz="0 0 0.20"/>
    <axis xyz="0 0 1"/>
    <limit effort="204" lower="-2.96705972839" upper="2.96705972839" velocity="2.26892802759"/>
    <safety_controller k_position="30" k_velocity="30" soft_lower_limit="-2.93215314335" soft_upper_limit="2.93215314335"/>
    <dynamics damping="1.0"/>
    <parent link="rightArm_arm_2_link"/>
    <child link="rightArm_arm_3_link"/>
  </joint>
  <link name="rightArm_arm_3_link">
    <inertial>
      <mass value="2.0"/>
      <origin rpy="0 0 0" xyz="0 0.06 0.130"/>
      <inertia ixx="0.0136666666667" ixy="0" ixz="0" iyy="0.003" iyz="0" izz="0.0118666666667"/>
    </inertial>
    <visual>
      <origin rpy="0 0 0" xyz="0 0 -0.008"/>
      <geometry>
        <mesh filename="package://uibk_robot/meshes/lwr/link_3.STL"/>
      </geometry>
      <material name="Orange"/>
    </visual>
    <!--
      <collision>
        <origin xyz="0 0 0" rpy="0 0 ${M_PI}"/>
        <geometry>
          <mesh filename="package://uibk_robot/meshes/lwr/convex/arm_segment_a_convex.stl"/>
        </geometry>
      </collision>
-->
    <collision>
      <origin rpy="0 0 0" xyz="0 0 0.0"/>
      <geometry>
        <sphere radius="0.07"/>
      </geometry>
    </collision>
    <collision>
      <origin rpy="0 0 0" xyz="0 0.06 0.2"/>
      <geometry>
        <sphere radius="0.07"/>
      </geometry>
    </collision>
    <collision>
      <origin rpy="-0.291 0 0" xyz="0 0.03 0.1"/>
      <geometry>
        <cylinder length="0.208" radius="0.07"/>
      </geometry>
    </collision>
  </link>
  <gazebo reference="rightArm_arm_3_link">
    <gravity>false</gravity>
  </gazebo>
  <transmission name="rightArm_arm_2_trans" type="SimpleTransmission">
    <actuator name="rightArm_arm_2_motor"/>
    <joint name="rightArm_arm_2_joint"/>
    <mechanicalReduction>1.0</mechanicalReduction>
  </transmission>
  <joint name="rightArm_arm_3_joint" type="revolute">
    <origin rpy="0 0 0" xyz="0 0 0.20"/>
    <axis xyz="0 -1 0"/>
    <limit effort="306" lower="-2.09439510239" upper="2.09439510239" velocity="2.26892802759"/>
    <safety_controller k_position="30" k_velocity="30" soft_lower_limit="-2.05948851735" soft_upper_limit="2.05948851735"/>
    <dynamics damping="1.0"/>
    <parent link="rightArm_arm_3_link"/>
    <child link="rightArm_arm_4_link"/>
  </joint>
  <link name="rightArm_arm_4_link">
    <inertial>
      <mass value="2.0"/>
      <origin rpy="0 0 0" xyz="0 -0.06 0.07"/>
      <inertia ixx="0.0136666666667" ixy="0" ixz="0" iyy="0.003" iyz="0" izz="0.0118666666667"/>
    </inertial>
    <visual>
      <origin rpy="0 0 0" xyz="0 0 0.0"/>
      <geometry>
        <mesh filename="package://uibk_robot/meshes/lwr/link_4.STL"/>
      </geometry>
      <material name="Orange"/>
    </visual>
    <!--
      <collision>
        <origin xyz="0 0 0.2" rpy="0 ${M_PI} 0"/>
        <geometry>
          <mesh filename="package://uibk_robot/meshes/lwr/convex/arm_segment_b_convex.stl"/>
        </geometry>
      </collision>
-->
    <collision>
      <origin rpy="0 0 0" xyz="0 0 0.2"/>
      <geometry>
        <sphere radius="0.07"/>
      </geometry>
    </collision>
    <collision>
      <origin rpy="0 0 0" xyz="0 -0.06 0.0"/>
      <geometry>
        <sphere radius="0.07"/>
      </geometry>
    </collision>
    <collision>
      <origin rpy="-0.291 0 0" xyz="0 -0.03 0.1"/>
      <geometry>
        <cylinder length="0.208" radius="0.07"/>
      </geometry>
    </collision>
  </link>
  <gazebo reference="rightArm_arm_4_link">
    <gravity>false</gravity>
  </gazebo>
  <transmission name="rightArm_arm_3_trans" type="SimpleTransmission">
    <actuator name="rightArm_arm_3_motor"/>
    <joint name="rightArm_arm_3_joint"/>
    <mechanicalReduction>1.0</mechanicalReduction>
  </transmission>
  <joint name="rightArm_arm_4_joint" type="revolute">
    <origin rpy="0 0 0" xyz="0 0 0.20"/>
    <axis xyz="0 0 1"/>
    <limit effort="204" lower="-2.96705972839" upper="2.96705972839" velocity="2.26892802759"/>
    <safety_controller k_position="30" k_velocity="30" soft_lower_limit="-2.93215314335" soft_upper_limit="2.93215314335"/>
    <dynamics damping="1.0"/>
    <parent link="rightArm_arm_4_link"/>
    <child link="rightArm_arm_5_link"/>
  </joint>
  <link name="rightArm_arm_5_link">
    <inertial>
      <mass value="2.0"/>
      <origin rpy="0 0 0" xyz="0 0 0.124"/>
      <inertia ixx="0.0126506666667" ixy="0" ixz="0" iyy="0.003" iyz="0" izz="0.0108506666667"/>
    </inertial>
    <visual>
      <origin rpy="0 0 0" xyz="0 0 -0.008"/>
      <geometry name="rightArm_arm_5_geom">
        <mesh filename="package://uibk_robot/meshes/lwr/link_5.STL"/>
      </geometry>
      <material name="Orange"/>
    </visual>
    <!--
      <collision>
        <origin xyz="0 0 0" rpy="0 0 0"/>
        <geometry>
          <mesh filename="package://uibk_robot/meshes/lwr/convex/arm_segment_last_convex.stl"/>
        </geometry>
      </collision>
-->
    <collision>
      <origin rpy="0 0 0" xyz="0 0 0.0"/>
      <geometry>
        <sphere radius="0.07"/>
      </geometry>
    </collision>
    <collision>
      <origin rpy="0 0 0" xyz="0 -0.04 0.19"/>
      <geometry>
        <sphere radius="0.07"/>
      </geometry>
    </collision>
    <collision>
      <origin rpy="0.207 0 0" xyz="0 -0.02 0.095"/>
      <geometry>
        <cylinder length="0.198" radius="0.07"/>
      </geometry>
    </collision>
  </link>
  <gazebo reference="rightArm_arm_5_link">
    <gravity>false</gravity>
  </gazebo>
  <transmission name="rightArm_arm_4_trans" type="SimpleTransmission">
    <actuator name="rightArm_arm_4_motor"/>
    <joint name="rightArm_arm_4_joint"/>
    <mechanicalReduction>1.0</mechanicalReduction>
  </transmission>
  <joint name="rightArm_arm_5_joint" type="revolute">
    <origin rpy="0 0 0" xyz="0 0 0.19"/>
    <axis xyz="0 1 0"/>
    <limit effort="306" lower="-2.09439510239" upper="2.09439510239" velocity="3.14159265359"/>
    <safety_controller k_position="30" k_velocity="30" soft_lower_limit="-2.05948851735" soft_upper_limit="2.05948851735"/>
    <dynamics damping="1.0"/>
    <parent link="rightArm_arm_5_link"/>
    <child link="rightArm_arm_6_link"/>
  </joint>
  <link name="rightArm_arm_6_link">
    <inertial>
      <mass value="0.2"/>
      <origin rpy="0 0 0" xyz="0 0 0.0625"/>
      <inertia ixx="0.000520833333333" ixy="0" ixz="0" iyy="0.000520833333333" iyz="0" izz="0.000520833333333"/>
    </inertial>
    <visual>
      <origin rpy="0 0 0" xyz="0 0 0"/>
      <geometry>
        <mesh filename="package://uibk_robot/meshes/lwr/link_6.STL"/>
      </geometry>
      <material name="Grey"/>
    </visual>
    <collision>
      <origin rpy="0 0 0" xyz="0 0 0"/>
      <geometry>
        <mesh filename="package://uibk_robot/meshes/lwr/convex/arm_wrist_convex.stl"/>
      </geometry>
    </collision>
  </link>
  <gazebo reference="rightArm_arm_6_link">
    <gravity>false</gravity>
  </gazebo>
  <transmission name="rightArm_arm_5_trans" type="SimpleTransmission">
    <actuator name="rightArm_arm_5_motor"/>
    <joint name="rightArm_arm_5_joint"/>
    <mechanicalReduction>1.0</mechanicalReduction>
  </transmission>
  <joint name="rightArm_arm_6_joint" type="revolute">
    <origin rpy="0 0 3.14159265359" xyz="0 0 0.078"/>
    <axis xyz="0 0 1"/>
    <limit effort="204" lower="-2.96705972839" upper="2.96705972839" velocity="3.14159265359"/>
    <safety_controller k_position="30" k_velocity="30" soft_lower_limit="-2.93215314335" soft_upper_limit="2.93215314335"/>
    <dynamics damping="1.0"/>
    <parent link="rightArm_arm_6_link"/>
    <child link="rightArm_arm_7_link"/>
  </joint>
  <link name="rightArm_arm_7_link">
    <inertial>
      <mass value="0.2"/>
      <origin xyz="0 0 0"/>
      <inertia ixx="0.0333333333333" ixy="0" ixz="0" iyy="0.0333333333333" iyz="0" izz="0.0333333333333"/>
    </inertial>
    <visual>
      <origin rpy="0 0 0" xyz="0 0 0"/>
      <geometry>
        <mesh filename="package://uibk_robot/meshes/lwr/link_7.STL"/>
      </geometry>
      <material name="DarkGrey"/>
    </visual>
    <collision>
      <origin rpy="0 0 -0.785398163397" xyz="0 0 0"/>
      <geometry>
        <cylinder length="0.05" radius="0.04"/>
      </geometry>
    </collision>
  </link>
  <gazebo reference="rightArm_arm_7_link">
    <gravity>false</gravity>
  </gazebo>
  <transmission name="rightArm_arm_6_trans" type="SimpleTransmission">
    <actuator name="rightArm_arm_6_motor"/>
    <joint name="rightArm_arm_6_joint"/>
    <mechanicalReduction>1.0</mechanicalReduction>
  </transmission>
  <joint name="leftGripper_palm_joint" type="fixed">
    <origin rpy="0 0 0" xyz="0 0 0"/>
    <parent link="leftArm_arm_7_link"/>
    <child link="leftGripper_palm_link"/>
  </joint>
  <link name="leftGripper_palm_link">
    <inertial>
      <origin rpy="0 0 0" xyz="0 0 0"/>
      <mass value="1"/>
      <inertia ixx="0.01" ixy="0" ixz="0" iyy="0.01" iyz="0" izz="0.01"/>
    </inertial>
    <visual>
      <origin rpy="0 0 0" xyz="0 0 0"/>
      <geometry>
        <mesh filename="package://schunk_description/meshes/sdh/palm.stl"/>
      </geometry>
      <material name="Schunk/LightGrey"/>
    </visual>
    <collision>
      <origin rpy="0 0 0" xyz="0 0 0"/>
      <geometry>
        <mesh filename="package://schunk_description/meshes/sdh/palm.stl"/>
      </geometry>
    </collision>
  </link>
  <joint name="leftGripper_grasp_joint" type="fixed">
    <origin rpy="0 0 0" xyz="0 0 0.15"/>
    <parent link="leftGripper_palm_link"/>
    <child link="leftGripper_grasp_link"/>
  </joint>
  <link name="leftGripper_grasp_link"/>
  <joint name="leftGripper_tip_joint" type="fixed">
    <origin rpy="0 0 0" xyz="0 0 0.22"/>
    <parent link="leftGripper_palm_link"/>
    <child link="leftGripper_tip_link"/>
  </joint>
  <link name="leftGripper_tip_link"/>
  <joint name="leftGripper_knuckle_joint" type="revolute">
    <origin rpy="0 0 3.14159265" xyz="0.01905 0.033 0.0745"/>
    <parent link="leftGripper_palm_link"/>
    <child link="leftGripper_finger_11_link"/>
    <axis xyz="0 0 1"/>
    <dynamics damping="1"/>
    <limit effort="100" lower="0" upper="1.570796327" velocity="5"/>
  </joint>
  <link name="leftGripper_finger_11_link">
    <inertial>
      <origin rpy="0 0 0" xyz="0 0 0"/>
      <mass value="0.1"/>
      <inertia ixx="0.01" ixy="0" ixz="0" iyy="0.01" iyz="0" izz="0.01"/>
    </inertial>
    <visual>
      <origin rpy="0 0 0" xyz="0 0 0"/>
      <geometry>
        <mesh filename="package://schunk_description/meshes/sdh/knuckle.stl"/>
      </geometry>
      <material name="Schunk/LightGrey"/>
    </visual>
    <collision>
      <origin rpy="0 0 0" xyz="0 0 0"/>
      <geometry>
        <mesh filename="package://schunk_description/meshes/sdh/knuckle.stl"/>
      </geometry>
    </collision>
  </link>
  <joint name="leftGripper_finger_12_joint" type="revolute">
    <origin rpy="0 0 0" xyz="0 0 0.0165"/>
    <parent link="leftGripper_finger_11_link"/>
    <child link="leftGripper_finger_12_link"/>
    <axis xyz="0 1 0"/>
    <dynamics damping="1"/>
    <limit effort="100" lower="-1.570796327" upper="1.570796327" velocity="5"/>
  </joint>
  <link name="leftGripper_finger_12_link">
    <inertial>
      <origin rpy="0 0 0" xyz="0 0 0"/>
      <mass value="0.1"/>
      <inertia ixx="0.01" ixy="0" ixz="0" iyy="0.01" iyz="0" izz="0.01"/>
    </inertial>
    <visual>
      <origin rpy="0 0 0" xyz="0 0 0"/>
      <geometry>
        <mesh filename="package://schunk_description/meshes/sdh/finger.stl"/>
      </geometry>
      <material name="Schunk/LightGrey"/>
    </visual>
    <collision>
      <origin rpy="0 0 0" xyz="0 0 0"/>
      <geometry>
        <mesh filename="package://schunk_description/meshes/sdh/finger.stl"/>
      </geometry>
    </collision>
  </link>
  <joint name="leftGripper_finger_13_joint" type="revolute">
    <origin rpy="0 0 0" xyz="0 0 0.0865"/>
    <parent link="leftGripper_finger_12_link"/>
    <child link="leftGripper_finger_13_link"/>
    <axis xyz="0 1 0"/>
    <dynamics damping="1"/>
    <limit effort="100" lower="-1.570796327" upper="1.570796327" velocity="5"/>
  </joint>
  <link name="leftGripper_finger_13_link">
    <inertial>
      <origin rpy="0 0 0" xyz="0 0 0"/>
      <mass value="0.1"/>
      <inertia ixx="0.01" ixy="0" ixz="0" iyy="0.01" iyz="0" izz="0.01"/>
    </inertial>
    <visual>
      <origin rpy="0 0 0" xyz="0 0 0"/>
      <geometry>
        <mesh filename="package://schunk_description/meshes/sdh/finger_tip.stl"/>
      </geometry>
      <material name="Schunk/LightGrey"/>
    </visual>
    <collision>
      <origin rpy="0 0 0" xyz="0 0 0"/>
      <geometry>
        <mesh filename="package://schunk_description/meshes/sdh/finger_tip.stl"/>
      </geometry>
    </collision>
  </link>
  <joint name="leftGripper_finger_21_joint" type="revolute">
    <mimic joint="leftGripper_knuckle_joint" multiplier="1" offset="0"/>
    <origin rpy="0 0 3.14159265" xyz="0.01905 -0.033 0.0745"/>
    <parent link="leftGripper_palm_link"/>
    <child link="leftGripper_finger_21_link"/>
    <axis xyz="0 0 -1"/>
    <dynamics damping="1"/>
    <limit effort="100" lower="0" upper="1.570796327" velocity="5"/>
  </joint>
  <link name="leftGripper_finger_21_link">
    <inertial>
      <origin rpy="0 0 0" xyz="0 0 0"/>
      <mass value="0.1"/>
      <inertia ixx="0.01" ixy="0" ixz="0" iyy="0.01" iyz="0" izz="0.01"/>
    </inertial>
    <visual>
      <origin rpy="0 0 0" xyz="0 0 0"/>
      <geometry>
        <mesh filename="package://schunk_description/meshes/sdh/knuckle.stl"/>
      </geometry>
      <material name="Schunk/LightGrey"/>
    </visual>
    <collision>
      <origin rpy="0 0 0" xyz="0 0 0"/>
      <geometry>
        <mesh filename="package://schunk_description/meshes/sdh/knuckle.stl"/>
      </geometry>
    </collision>
  </link>
  <joint name="leftGripper_finger_22_joint" type="revolute">
    <origin rpy="0 0 0" xyz="0 0 0.0165"/>
    <parent link="leftGripper_finger_21_link"/>
    <child link="leftGripper_finger_22_link"/>
    <axis xyz="0 1 0"/>
    <dynamics damping="1"/>
    <limit effort="100" lower="-1.570796327" upper="1.570796327" velocity="5"/>
  </joint>
  <link name="leftGripper_finger_22_link">
    <inertial>
      <origin rpy="0 0 0" xyz="0 0 0"/>
      <mass value="0.1"/>
      <inertia ixx="0.01" ixy="0" ixz="0" iyy="0.01" iyz="0" izz="0.01"/>
    </inertial>
    <visual>
      <origin rpy="0 0 0" xyz="0 0 0"/>
      <geometry>
        <mesh filename="package://schunk_description/meshes/sdh/finger.stl"/>
      </geometry>
      <material name="Schunk/LightGrey"/>
    </visual>
    <collision>
      <origin rpy="0 0 0" xyz="0 0 0"/>
      <geometry>
        <mesh filename="package://schunk_description/meshes/sdh/finger.stl"/>
      </geometry>
    </collision>
  </link>
  <joint name="leftGripper_finger_23_joint" type="revolute">
    <origin rpy="0 0 0" xyz="0 0 0.0865"/>
    <parent link="leftGripper_finger_22_link"/>
    <child link="leftGripper_finger_23_link"/>
    <axis xyz="0 1 0"/>
    <dynamics damping="1"/>
    <limit effort="100" lower="-1.570796327" upper="1.570796327" velocity="5"/>
  </joint>
  <link name="leftGripper_finger_23_link">
    <inertial>
      <origin rpy="0 0 0" xyz="0 0 0"/>
      <mass value="0.1"/>
      <inertia ixx="0.01" ixy="0" ixz="0" iyy="0.01" iyz="0" izz="0.01"/>
    </inertial>
    <visual>
      <origin rpy="0 0 0" xyz="0 0 0"/>
      <geometry>
        <mesh filename="package://schunk_description/meshes/sdh/finger_tip.stl"/>
      </geometry>
      <material name="Schunk/LightGrey"/>
    </visual>
    <collision>
      <origin rpy="0 0 0" xyz="0 0 0"/>
      <geometry>
        <mesh filename="package://schunk_description/meshes/sdh/finger_tip.stl"/>
      </geometry>
    </collision>
  </link>
  <joint name="leftGripper_thumb_1_joint" type="fixed">
    <origin rpy="0 0 0" xyz="-0.03811 0 0.0745 "/>
    <parent link="leftGripper_palm_link"/>
    <child link="leftGripper_thumb_1_link"/>
  </joint>
  <link name="leftGripper_thumb_1_link">
    <inertial>
      <origin rpy="0 0 0" xyz="0 0 0"/>
      <mass value="0.1"/>
      <inertia ixx="0.01" ixy="0" ixz="0" iyy="0.01" iyz="0" izz="0.01"/>
    </inertial>
    <visual>
      <origin rpy="0 0 0" xyz="0 0 0"/>
      <geometry>
        <mesh filename="package://schunk_description/meshes/sdh/knuckle.stl"/>
      </geometry>
      <material name="Schunk/LightGrey"/>
    </visual>
    <collision>
      <origin rpy="0 0 0" xyz="0 0 0"/>
      <geometry>
        <mesh filename="package://schunk_description/meshes/sdh/knuckle.stl"/>
      </geometry>
    </collision>
  </link>
  <joint name="leftGripper_thumb_2_joint" type="revolute">
    <origin rpy="0 0 0" xyz="0 0 0.0165"/>
    <parent link="leftGripper_thumb_1_link"/>
    <child link="leftGripper_thumb_2_link"/>
    <axis xyz="0 1 0"/>
    <dynamics damping="1"/>
    <limit effort="100" lower="-1.570796327" upper="1.570796327" velocity="5"/>
  </joint>
  <link name="leftGripper_thumb_2_link">
    <inertial>
      <origin rpy="0 0 0" xyz="0 0 0"/>
      <mass value="0.1"/>
      <inertia ixx="0.01" ixy="0" ixz="0" iyy="0.01" iyz="0" izz="0.01"/>
    </inertial>
    <visual>
      <origin rpy="0 0 0" xyz="0 0 0"/>
      <geometry>
        <mesh filename="package://schunk_description/meshes/sdh/finger.stl"/>
      </geometry>
      <material name="Schunk/LightGrey"/>
    </visual>
    <collision>
      <origin rpy="0 0 0" xyz="0 0 0"/>
      <geometry>
        <mesh filename="package://schunk_description/meshes/sdh/finger.stl"/>
      </geometry>
    </collision>
  </link>
  <joint name="leftGripper_thumb_3_joint" type="revolute">
    <origin rpy="0 0 0" xyz="0 0 0.0865"/>
    <parent link="leftGripper_thumb_2_link"/>
    <child link="leftGripper_thumb_3_link"/>
    <axis xyz="0 1 0"/>
    <dynamics damping="1"/>
    <limit effort="100" lower="-1.570796327" upper="1.570796327" velocity="5"/>
  </joint>
  <link name="leftGripper_thumb_3_link">
    <inertial>
      <origin rpy="0 0 0" xyz="0 0 0"/>
      <mass value="0.1"/>
      <inertia ixx="0.01" ixy="0" ixz="0" iyy="0.01" iyz="0" izz="0.01"/>
    </inertial>
    <visual>
      <origin rpy="0 0 0" xyz="0 0 0"/>
      <geometry>
        <mesh filename="package://schunk_description/meshes/sdh/finger_tip.stl"/>
      </geometry>
      <material name="Schunk/LightGrey"/>
    </visual>
    <collision>
      <origin rpy="0 0 0" xyz="0 0 0"/>
      <geometry>
        <mesh filename="package://schunk_description/meshes/sdh/finger_tip.stl"/>
      </geometry>
    </collision>
  </link>
  <gazebo reference="leftGripper_palm_link">
    <material>Schunk/LightGrey</material>
    <turnGravityOff>false</turnGravityOff>
  </gazebo>
  <gazebo reference="leftGripper_finger_11_link">
    <material>Schunk/LightGrey</material>
    <turnGravityOff>false</turnGravityOff>
  </gazebo>
  <gazebo reference="leftGripper_finger_12_link">
    <selfCollide>true</selfCollide>
    <sensor name="leftGripper_finger_12_contact_sensor" type="contact">
      <always_on>true</always_on>
      <update_rate>100</update_rate>
      <contact>
        <collision>leftGripper_finger_12_link_geom</collision>
      </contact>
      <plugin filename="libgazebo_ros_bumper.so" name="leftGripper_finger_12_gazebo_ros_bumper_controller">
        <alwaysOn>true</alwaysOn>
        <updateRate>100.0</updateRate>
        <frameName>leftGripper_finger_12_link</frameName>
        <bumperTopicName>leftGripper_finger_12_bumper</bumperTopicName>
      </plugin>
    </sensor>
    <material>Schunk/LightGrey</material>
    <turnGravityOff>false</turnGravityOff>
  </gazebo>
  <gazebo reference="leftGripper_finger_13_link">
    <selfCollide>true</selfCollide>
    <sensor name="leftGripper_finger_13_contact_sensor" type="contact">
      <always_on>true</always_on>
      <update_rate>100</update_rate>
      <contact>
        <collision>leftGripper_finger_13_link_geom</collision>
      </contact>
      <plugin filename="libgazebo_ros_bumper.so" name="leftGripper_finger_13_gazebo_ros_bumper_controller">
        <alwaysOn>true</alwaysOn>
        <updateRate>100.0</updateRate>
        <frameName>leftGripper_finger_13_link</frameName>
        <bumperTopicName>leftGripper_finger_13_bumper</bumperTopicName>
      </plugin>
    </sensor>
    <material>Schunk/LightGrey</material>
  </gazebo>
  <gazebo reference="leftGripper_finger_21_link">
    <material>Schunk/LightGrey</material>
    <turnGravityOff>false</turnGravityOff>
  </gazebo>
  <gazebo reference="leftGripper_finger_22_link">
    <selfCollide>true</selfCollide>
    <sensor name="leftGripper_finger_22_contact_sensor" type="contact">
      <always_on>true</always_on>
      <update_rate>100</update_rate>
      <contact>
        <collision>leftGripper_finger_22_link_geom</collision>
      </contact>
      <plugin filename="libgazebo_ros_bumper.so" name="leftGripper_finger_22_gazebo_ros_bumper_controller">
        <alwaysOn>true</alwaysOn>
        <updateRate>100.0</updateRate>
        <frameName>leftGripper_finger_22_link</frameName>
        <bumperTopicName>leftGripper_finger_22_bumper</bumperTopicName>
      </plugin>
    </sensor>
    <material>Schunk/LightGrey</material>
    <turnGravityOff>false</turnGravityOff>
  </gazebo>
  <gazebo reference="leftGripper_finger_23_link">
    <selfCollide>true</selfCollide>
    <sensor name="leftGripper_finger_23_contact_sensor" type="contact">
      <always_on>true</always_on>
      <update_rate>100</update_rate>
      <contact>
        <collision>leftGripper_finger_23_link_geom</collision>
      </contact>
      <plugin filename="libgazebo_ros_bumper.so" name="leftGripper_finger_23_gazebo_ros_bumper_controller">
        <alwaysOn>true</alwaysOn>
        <updateRate>100.0</updateRate>
        <frameName>leftGripper_finger_23_link</frameName>
        <bumperTopicName>leftGripper_finger_23_bumper</bumperTopicName>
      </plugin>
    </sensor>
    <material>Schunk/LightGrey</material>
  </gazebo>
  <gazebo reference="leftGripper_thumb_1_link">
    <material>Schunk/LightGrey</material>
    <turnGravityOff>false</turnGravityOff>
  </gazebo>
  <gazebo reference="leftGripper_thumb_2_link">
    <selfCollide>true</selfCollide>
    <sensor name="leftGripper_thumb_2_contact_sensor" type="contact">
      <always_on>true</always_on>
      <update_rate>100</update_rate>
      <contact>
        <collision>leftGripper_thumb_2_link_geom</collision>
      </contact>
      <plugin filename="libgazebo_ros_bumper.so" name="leftGripper_thumb_2_gazebo_ros_bumper_controller">
        <alwaysOn>true</alwaysOn>
        <updateRate>100.0</updateRate>
        <frameName>leftGripper_thumb_2_link</frameName>
        <bumperTopicName>leftGripper_thumb_2_bumper</bumperTopicName>
      </plugin>
    </sensor>
    <material>Schunk/LightGrey</material>
    <turnGravityOff>false</turnGravityOff>
  </gazebo>
  <gazebo reference="leftGripper_thumb_3_link">
    <selfCollide>true</selfCollide>
    <sensor name="leftGripper_thumb_3_contact_sensor" type="contact">
      <always_on>true</always_on>
      <update_rate>100</update_rate>
      <contact>
        <collision>leftGripper_thumb_3_link_geom</collision>
      </contact>
      <plugin filename="libgazebo_ros_bumper.so" name="leftGripper_thumb_3_gazebo_ros_bumper_controller">
        <alwaysOn>true</alwaysOn>
        <updateRate>100.0</updateRate>
        <frameName>leftGripper_thumb_3_link</frameName>
        <bumperTopicName>leftGripper_thumb_3_bumper</bumperTopicName>
      </plugin>
    </sensor>
    <material>Schunk/LightGrey</material>
  </gazebo>
  <transmission name="leftGripper_knuckle_trans" type="pr2_mechanism_model/SimpleTransmission">
    <actuator name="leftGripper_knuckle_motor"/>
    <joint name="leftGripper_finger_21_joint"/>
    <mechanicalReduction>1</mechanicalReduction>
  </transmission>
  <transmission name="leftGripper_knuckle_trans" type="pr2_mechanism_model/SimpleTransmission">
    <actuator name="leftGripper_knuckle_motor"/>
    <joint name="leftGripper_knuckle_joint"/>
    <mechanicalReduction>1</mechanicalReduction>
  </transmission>
  <transmission name="leftGripper_finger_12_trans" type="pr2_mechanism_model/SimpleTransmission">
    <actuator name="leftGripper_finger_12_motor"/>
    <joint name="leftGripper_finger_12_joint"/>
    <mechanicalReduction>1</mechanicalReduction>
  </transmission>
  <transmission name="leftGripper_finger_13_trans" type="pr2_mechanism_model/SimpleTransmission">
    <actuator name="leftGripper_finger_13_motor"/>
    <joint name="leftGripper_finger_13_joint"/>
    <mechanicalReduction>1</mechanicalReduction>
  </transmission>
  <transmission name="leftGripper_finger_22_trans" type="pr2_mechanism_model/SimpleTransmission">
    <actuator name="leftGripper_finger_22_motor"/>
    <joint name="leftGripper_finger_22_joint"/>
    <mechanicalReduction>1</mechanicalReduction>
  </transmission>
  <transmission name="leftGripper_finger_23_trans" type="pr2_mechanism_model/SimpleTransmission">
    <actuator name="leftGripper_finger_23_motor"/>
    <joint name="leftGripper_finger_23_joint"/>
    <mechanicalReduction>1</mechanicalReduction>
  </transmission>
  <transmission name="leftGripper_thumb_2_trans" type="pr2_mechanism_model/SimpleTransmission">
    <actuator name="leftGripper_thumb_2_motor"/>
    <joint name="leftGripper_thumb_2_joint"/>
    <mechanicalReduction>1</mechanicalReduction>
  </transmission>
  <transmission name="leftGripper_thumb_3_trans" type="pr2_mechanism_model/SimpleTransmission">
    <actuator name="leftGripper_thumb_3_motor"/>
    <joint name="leftGripper_thumb_3_joint"/>
    <mechanicalReduction>1</mechanicalReduction>
  </transmission>
  <joint name="rightGripper_palm_joint" type="fixed">
    <origin rpy="0 0 0" xyz="0 0 0"/>
    <parent link="rightArm_arm_7_link"/>
    <child link="rightGripper_palm_link"/>
  </joint>
  <link name="rightGripper_palm_link">
    <inertial>
      <origin rpy="0 0 0" xyz="0 0 0"/>
      <mass value="1"/>
      <inertia ixx="0.01" ixy="0" ixz="0" iyy="0.01" iyz="0" izz="0.01"/>
    </inertial>
    <visual>
      <origin rpy="0 0 0" xyz="0 0 0"/>
      <geometry>
        <mesh filename="package://schunk_description/meshes/sdh/palm.stl"/>
      </geometry>
      <material name="Schunk/LightGrey"/>
    </visual>
    <collision>
      <origin rpy="0 0 0" xyz="0 0 0"/>
      <geometry>
        <mesh filename="package://schunk_description/meshes/sdh/palm.stl"/>
      </geometry>
    </collision>
  </link>
  <joint name="rightGripper_grasp_joint" type="fixed">
    <origin rpy="0 0 0" xyz="0 0 0.15"/>
    <parent link="rightGripper_palm_link"/>
    <child link="rightGripper_grasp_link"/>
  </joint>
  <link name="rightGripper_grasp_link"/>
  <joint name="rightGripper_tip_joint" type="fixed">
    <origin rpy="0 0 0" xyz="0 0 0.22"/>
    <parent link="rightGripper_palm_link"/>
    <child link="rightGripper_tip_link"/>
  </joint>
  <link name="rightGripper_tip_link"/>
  <joint name="rightGripper_knuckle_joint" type="revolute">
    <origin rpy="0 0 3.14159265" xyz="0.01905 0.033 0.0745"/>
    <parent link="rightGripper_palm_link"/>
    <child link="rightGripper_finger_11_link"/>
    <axis xyz="0 0 1"/>
    <dynamics damping="1"/>
    <limit effort="100" lower="0" upper="1.570796327" velocity="5"/>
  </joint>
  <link name="rightGripper_finger_11_link">
    <inertial>
      <origin rpy="0 0 0" xyz="0 0 0"/>
      <mass value="0.1"/>
      <inertia ixx="0.01" ixy="0" ixz="0" iyy="0.01" iyz="0" izz="0.01"/>
    </inertial>
    <visual>
      <origin rpy="0 0 0" xyz="0 0 0"/>
      <geometry>
        <mesh filename="package://schunk_description/meshes/sdh/knuckle.stl"/>
      </geometry>
      <material name="Schunk/LightGrey"/>
    </visual>
    <collision>
      <origin rpy="0 0 0" xyz="0 0 0"/>
      <geometry>
        <mesh filename="package://schunk_description/meshes/sdh/knuckle.stl"/>
      </geometry>
    </collision>
  </link>
  <joint name="rightGripper_finger_12_joint" type="revolute">
    <origin rpy="0 0 0" xyz="0 0 0.0165"/>
    <parent link="rightGripper_finger_11_link"/>
    <child link="rightGripper_finger_12_link"/>
    <axis xyz="0 1 0"/>
    <dynamics damping="1"/>
    <limit effort="100" lower="-1.570796327" upper="1.570796327" velocity="5"/>
  </joint>
  <link name="rightGripper_finger_12_link">
    <inertial>
      <origin rpy="0 0 0" xyz="0 0 0"/>
      <mass value="0.1"/>
      <inertia ixx="0.01" ixy="0" ixz="0" iyy="0.01" iyz="0" izz="0.01"/>
    </inertial>
    <visual>
      <origin rpy="0 0 0" xyz="0 0 0"/>
      <geometry>
        <mesh filename="package://schunk_description/meshes/sdh/finger.stl"/>
      </geometry>
      <material name="Schunk/LightGrey"/>
    </visual>
    <collision>
      <origin rpy="0 0 0" xyz="0 0 0"/>
      <geometry>
        <mesh filename="package://schunk_description/meshes/sdh/finger.stl"/>
      </geometry>
    </collision>
  </link>
  <joint name="rightGripper_finger_13_joint" type="revolute">
    <origin rpy="0 0 0" xyz="0 0 0.0865"/>
    <parent link="rightGripper_finger_12_link"/>
    <child link="rightGripper_finger_13_link"/>
    <axis xyz="0 1 0"/>
    <dynamics damping="1"/>
    <limit effort="100" lower="-1.570796327" upper="1.570796327" velocity="5"/>
  </joint>
  <link name="rightGripper_finger_13_link">
    <inertial>
      <origin rpy="0 0 0" xyz="0 0 0"/>
      <mass value="0.1"/>
      <inertia ixx="0.01" ixy="0" ixz="0" iyy="0.01" iyz="0" izz="0.01"/>
    </inertial>
    <visual>
      <origin rpy="0 0 0" xyz="0 0 0"/>
      <geometry>
        <mesh filename="package://schunk_description/meshes/sdh/finger_tip.stl"/>
      </geometry>
      <material name="Schunk/LightGrey"/>
    </visual>
    <collision>
      <origin rpy="0 0 0" xyz="0 0 0"/>
      <geometry>
        <mesh filename="package://schunk_description/meshes/sdh/finger_tip.stl"/>
      </geometry>
    </collision>
  </link>
  <joint name="rightGripper_finger_21_joint" type="revolute">
    <mimic joint="rightGripper_knuckle_joint" multiplier="1" offset="0"/>
    <origin rpy="0 0 3.14159265" xyz="0.01905 -0.033 0.0745"/>
    <parent link="rightGripper_palm_link"/>
    <child link="rightGripper_finger_21_link"/>
    <axis xyz="0 0 -1"/>
    <dynamics damping="1"/>
    <limit effort="100" lower="0" upper="1.570796327" velocity="5"/>
  </joint>
  <link name="rightGripper_finger_21_link">
    <inertial>
      <origin rpy="0 0 0" xyz="0 0 0"/>
      <mass value="0.1"/>
      <inertia ixx="0.01" ixy="0" ixz="0" iyy="0.01" iyz="0" izz="0.01"/>
    </inertial>
    <visual>
      <origin rpy="0 0 0" xyz="0 0 0"/>
      <geometry>
        <mesh filename="package://schunk_description/meshes/sdh/knuckle.stl"/>
      </geometry>
      <material name="Schunk/LightGrey"/>
    </visual>
    <collision>
      <origin rpy="0 0 0" xyz="0 0 0"/>
      <geometry>
        <mesh filename="package://schunk_description/meshes/sdh/knuckle.stl"/>
      </geometry>
    </collision>
  </link>
  <joint name="rightGripper_finger_22_joint" type="revolute">
    <origin rpy="0 0 0" xyz="0 0 0.0165"/>
    <parent link="rightGripper_finger_21_link"/>
    <child link="rightGripper_finger_22_link"/>
    <axis xyz="0 1 0"/>
    <dynamics damping="1"/>
    <limit effort="100" lower="-1.570796327" upper="1.570796327" velocity="5"/>
  </joint>
  <link name="rightGripper_finger_22_link">
    <inertial>
      <origin rpy="0 0 0" xyz="0 0 0"/>
      <mass value="0.1"/>
      <inertia ixx="0.01" ixy="0" ixz="0" iyy="0.01" iyz="0" izz="0.01"/>
    </inertial>
    <visual>
      <origin rpy="0 0 0" xyz="0 0 0"/>
      <geometry>
        <mesh filename="package://schunk_description/meshes/sdh/finger.stl"/>
      </geometry>
      <material name="Schunk/LightGrey"/>
    </visual>
    <collision>
      <origin rpy="0 0 0" xyz="0 0 0"/>
      <geometry>
        <mesh filename="package://schunk_description/meshes/sdh/finger.stl"/>
      </geometry>
    </collision>
  </link>
  <joint name="rightGripper_finger_23_joint" type="revolute">
    <origin rpy="0 0 0" xyz="0 0 0.0865"/>
    <parent link="rightGripper_finger_22_link"/>
    <child link="rightGripper_finger_23_link"/>
    <axis xyz="0 1 0"/>
    <dynamics damping="1"/>
    <limit effort="100" lower="-1.570796327" upper="1.570796327" velocity="5"/>
  </joint>
  <link name="rightGripper_finger_23_link">
    <inertial>
      <origin rpy="0 0 0" xyz="0 0 0"/>
      <mass value="0.1"/>
      <inertia ixx="0.01" ixy="0" ixz="0" iyy="0.01" iyz="0" izz="0.01"/>
    </inertial>
    <visual>
      <origin rpy="0 0 0" xyz="0 0 0"/>
      <geometry>
        <mesh filename="package://schunk_description/meshes/sdh/finger_tip.stl"/>
      </geometry>
      <material name="Schunk/LightGrey"/>
    </visual>
    <collision>
      <origin rpy="0 0 0" xyz="0 0 0"/>
      <geometry>
        <mesh filename="package://schunk_description/meshes/sdh/finger_tip.stl"/>
      </geometry>
    </collision>
  </link>
  <joint name="rightGripper_thumb_1_joint" type="fixed">
    <origin rpy="0 0 0" xyz="-0.03811 0 0.0745 "/>
    <parent link="rightGripper_palm_link"/>
    <child link="rightGripper_thumb_1_link"/>
  </joint>
  <link name="rightGripper_thumb_1_link">
    <inertial>
      <origin rpy="0 0 0" xyz="0 0 0"/>
      <mass value="0.1"/>
      <inertia ixx="0.01" ixy="0" ixz="0" iyy="0.01" iyz="0" izz="0.01"/>
    </inertial>
    <visual>
      <origin rpy="0 0 0" xyz="0 0 0"/>
      <geometry>
        <mesh filename="package://schunk_description/meshes/sdh/knuckle.stl"/>
      </geometry>
      <material name="Schunk/LightGrey"/>
    </visual>
    <collision>
      <origin rpy="0 0 0" xyz="0 0 0"/>
      <geometry>
        <mesh filename="package://schunk_description/meshes/sdh/knuckle.stl"/>
      </geometry>
    </collision>
  </link>
  <joint name="rightGripper_thumb_2_joint" type="revolute">
    <origin rpy="0 0 0" xyz="0 0 0.0165"/>
    <parent link="rightGripper_thumb_1_link"/>
    <child link="rightGripper_thumb_2_link"/>
    <axis xyz="0 1 0"/>
    <dynamics damping="1"/>
    <limit effort="100" lower="-1.570796327" upper="1.570796327" velocity="5"/>
  </joint>
  <link name="rightGripper_thumb_2_link">
    <inertial>
      <origin rpy="0 0 0" xyz="0 0 0"/>
      <mass value="0.1"/>
      <inertia ixx="0.01" ixy="0" ixz="0" iyy="0.01" iyz="0" izz="0.01"/>
    </inertial>
    <visual>
      <origin rpy="0 0 0" xyz="0 0 0"/>
      <geometry>
        <mesh filename="package://schunk_description/meshes/sdh/finger.stl"/>
      </geometry>
      <material name="Schunk/LightGrey"/>
    </visual>
    <collision>
      <origin rpy="0 0 0" xyz="0 0 0"/>
      <geometry>
        <mesh filename="package://schunk_description/meshes/sdh/finger.stl"/>
      </geometry>
    </collision>
  </link>
  <joint name="rightGripper_thumb_3_joint" type="revolute">
    <origin rpy="0 0 0" xyz="0 0 0.0865"/>
    <parent link="rightGripper_thumb_2_link"/>
    <child link="rightGripper_thumb_3_link"/>
    <axis xyz="0 1 0"/>
    <dynamics damping="1"/>
    <limit effort="100" lower="-1.570796327" upper="1.570796327" velocity="5"/>
  </joint>
  <link name="rightGripper_thumb_3_link">
    <inertial>
      <origin rpy="0 0 0" xyz="0 0 0"/>
      <mass value="0.1"/>
      <inertia ixx="0.01" ixy="0" ixz="0" iyy="0.01" iyz="0" izz="0.01"/>
    </inertial>
    <visual>
      <origin rpy="0 0 0" xyz="0 0 0"/>
      <geometry>
        <mesh filename="package://schunk_description/meshes/sdh/finger_tip.stl"/>
      </geometry>
      <material name="Schunk/LightGrey"/>
    </visual>
    <collision>
      <origin rpy="0 0 0" xyz="0 0 0"/>
      <geometry>
        <mesh filename="package://schunk_description/meshes/sdh/finger_tip.stl"/>
      </geometry>
    </collision>
  </link>
  <gazebo reference="rightGripper_palm_link">
    <material>Schunk/LightGrey</material>
    <turnGravityOff>false</turnGravityOff>
  </gazebo>
  <gazebo reference="rightGripper_finger_11_link">
    <material>Schunk/LightGrey</material>
    <turnGravityOff>false</turnGravityOff>
  </gazebo>
  <gazebo reference="rightGripper_finger_12_link">
    <selfCollide>true</selfCollide>
    <sensor name="rightGripper_finger_12_contact_sensor" type="contact">
      <always_on>true</always_on>
      <update_rate>100</update_rate>
      <contact>
        <collision>rightGripper_finger_12_link_geom</collision>
      </contact>
      <plugin filename="libgazebo_ros_bumper.so" name="rightGripper_finger_12_gazebo_ros_bumper_controller">
        <alwaysOn>true</alwaysOn>
        <updateRate>100.0</updateRate>
        <frameName>rightGripper_finger_12_link</frameName>
        <bumperTopicName>rightGripper_finger_12_bumper</bumperTopicName>
      </plugin>
    </sensor>
    <material>Schunk/LightGrey</material>
    <turnGravityOff>false</turnGravityOff>
  </gazebo>
  <gazebo reference="rightGripper_finger_13_link">
    <selfCollide>true</selfCollide>
    <sensor name="rightGripper_finger_13_contact_sensor" type="contact">
      <always_on>true</always_on>
      <update_rate>100</update_rate>
      <contact>
        <collision>rightGripper_finger_13_link_geom</collision>
      </contact>
      <plugin filename="libgazebo_ros_bumper.so" name="rightGripper_finger_13_gazebo_ros_bumper_controller">
        <alwaysOn>true</alwaysOn>
        <updateRate>100.0</updateRate>
        <frameName>rightGripper_finger_13_link</frameName>
        <bumperTopicName>rightGripper_finger_13_bumper</bumperTopicName>
      </plugin>
    </sensor>
    <material>Schunk/LightGrey</material>
  </gazebo>
  <gazebo reference="rightGripper_finger_21_link">
    <material>Schunk/LightGrey</material>
    <turnGravityOff>false</turnGravityOff>
  </gazebo>
  <gazebo reference="rightGripper_finger_22_link">
    <selfCollide>true</selfCollide>
    <sensor name="rightGripper_finger_22_contact_sensor" type="contact">
      <always_on>true</always_on>
      <update_rate>100</update_rate>
      <contact>
        <collision>rightGripper_finger_22_link_geom</collision>
      </contact>
      <plugin filename="libgazebo_ros_bumper.so" name="rightGripper_finger_22_gazebo_ros_bumper_controller">
        <alwaysOn>true</alwaysOn>
        <updateRate>100.0</updateRate>
        <frameName>rightGripper_finger_22_link</frameName>
        <bumperTopicName>rightGripper_finger_22_bumper</bumperTopicName>
      </plugin>
    </sensor>
    <material>Schunk/LightGrey</material>
    <turnGravityOff>false</turnGravityOff>
  </gazebo>
  <gazebo reference="rightGripper_finger_23_link">
    <selfCollide>true</selfCollide>
    <sensor name="rightGripper_finger_23_contact_sensor" type="contact">
      <always_on>true</always_on>
      <update_rate>100</update_rate>
      <contact>
        <collision>rightGripper_finger_23_link_geom</collision>
      </contact>
      <plugin filename="libgazebo_ros_bumper.so" name="rightGripper_finger_23_gazebo_ros_bumper_controller">
        <alwaysOn>true</alwaysOn>
        <updateRate>100.0</updateRate>
        <frameName>rightGripper_finger_23_link</frameName>
        <bumperTopicName>rightGripper_finger_23_bumper</bumperTopicName>
      </plugin>
    </sensor>
    <material>Schunk/LightGrey</material>
  </gazebo>
  <gazebo reference="rightGripper_thumb_1_link">
    <material>Schunk/LightGrey</material>
    <turnGravityOff>false</turnGravityOff>
  </gazebo>
  <gazebo reference="rightGripper_thumb_2_link">
    <selfCollide>true</selfCollide>
    <sensor name="rightGripper_thumb_2_contact_sensor" type="contact">
      <always_on>true</always_on>
      <update_rate>100</update_rate>
      <contact>
        <collision>rightGripper_thumb_2_link_geom</collision>
      </contact>
      <plugin filename="libgazebo_ros_bumper.so" name="rightGripper_thumb_2_gazebo_ros_bumper_controller">
        <alwaysOn>true</alwaysOn>
        <updateRate>100.0</updateRate>
        <frameName>rightGripper_thumb_2_link</frameName>
        <bumperTopicName>rightGripper_thumb_2_bumper</bumperTopicName>
      </plugin>
    </sensor>
    <material>Schunk/LightGrey</material>
    <turnGravityOff>false</turnGravityOff>
  </gazebo>
  <gazebo reference="rightGripper_thumb_3_link">
    <selfCollide>true</selfCollide>
    <sensor name="rightGripper_thumb_3_contact_sensor" type="contact">
      <always_on>true</always_on>
      <update_rate>100</update_rate>
      <contact>
        <collision>rightGripper_thumb_3_link_geom</collision>
      </contact>
      <plugin filename="libgazebo_ros_bumper.so" name="rightGripper_thumb_3_gazebo_ros_bumper_controller">
        <alwaysOn>true</alwaysOn>
        <updateRate>100.0</updateRate>
        <frameName>rightGripper_thumb_3_link</frameName>
        <bumperTopicName>rightGripper_thumb_3_bumper</bumperTopicName>
      </plugin>
    </sensor>
    <material>Schunk/LightGrey</material>
  </gazebo>
  <transmission name="rightGripper_knuckle_trans" type="pr2_mechanism_model/SimpleTransmission">
    <actuator name="rightGripper_knuckle_motor"/>
    <joint name="rightGripper_finger_21_joint"/>
    <mechanicalReduction>1</mechanicalReduction>
  </transmission>
  <transmission name="rightGripper_knuckle_trans" type="pr2_mechanism_model/SimpleTransmission">
    <actuator name="rightGripper_knuckle_motor"/>
    <joint name="rightGripper_knuckle_joint"/>
    <mechanicalReduction>1</mechanicalReduction>
  </transmission>
  <transmission name="rightGripper_finger_12_trans" type="pr2_mechanism_model/SimpleTransmission">
    <actuator name="rightGripper_finger_12_motor"/>
    <joint name="rightGripper_finger_12_joint"/>
    <mechanicalReduction>1</mechanicalReduction>
  </transmission>
  <transmission name="rightGripper_finger_13_trans" type="pr2_mechanism_model/SimpleTransmission">
    <actuator name="rightGripper_finger_13_motor"/>
    <joint name="rightGripper_finger_13_joint"/>
    <mechanicalReduction>1</mechanicalReduction>
  </transmission>
  <transmission name="rightGripper_finger_22_trans" type="pr2_mechanism_model/SimpleTransmission">
    <actuator name="rightGripper_finger_22_motor"/>
    <joint name="rightGripper_finger_22_joint"/>
    <mechanicalReduction>1</mechanicalReduction>
  </transmission>
  <transmission name="rightGripper_finger_23_trans" type="pr2_mechanism_model/SimpleTransmission">
    <actuator name="rightGripper_finger_23_motor"/>
    <joint name="rightGripper_finger_23_joint"/>
    <mechanicalReduction>1</mechanicalReduction>
  </transmission>
  <transmission name="rightGripper_thumb_2_trans" type="pr2_mechanism_model/SimpleTransmission">
    <actuator name="rightGripper_thumb_2_motor"/>
    <joint name="rightGripper_thumb_2_joint"/>
    <mechanicalReduction>1</mechanicalReduction>
  </transmission>
  <transmission name="rightGripper_thumb_3_trans" type="pr2_mechanism_model/SimpleTransmission">
    <actuator name="rightGripper_thumb_3_motor"/>
    <joint name="rightGripper_thumb_3_joint"/>
    <mechanicalReduction>1</mechanicalReduction>
  </transmission>
</robot>

